<?xml version="1.0" ?>
<!-- =================================================================================== -->
<!-- |    This document was autogenerated by xacro from igvc.xacro                     | -->
<!-- |    EDITING THIS FILE BY HAND IS NOT RECOMMENDED                                 | -->
<!-- =================================================================================== -->
<!-- name="visual"-->
<robot name="igvc" xmlns:xacro="http://www.ros.org/wiki/xacro">
  <!-- 1.853" on plans -->
  <!-- 5.976" diameter on plans -->
  <!-- 2lbs on plans -->
  <!-- was 0.2 -->
  <!-- kp and kd were 1e6 and 100 (these used to be values for rubber) -->
  <!-- /////////////////////////////////////////////////////////////////////////////////////// -->
  <!-- Macros definition. -->
  <!-- /////////////////////////////////////////////////////////////////////////////////////// -->
  <material name="blue">
    <color rgba="0 0 .8 1"/>
  </material>
  <material name="black">
    <color rgba="0 0 0 1"/>
  </material>
  <material name="white">
    <color rgba="1 1 1 1"/>
  </material>
  <!-- /////////////////////////////////////////////////////////////////////////////////////// -->
  <!-- Wheel definition. -->
  <!-- /////////////////////////////////////////////////////////////////////////////////////// -->
  <!-- /////////////////////////////////////////////////////////////////////////////////////// -->
  <!-- Robot definition. -->
  <!-- /////////////////////////////////////////////////////////////////////////////////////// -->
  <link name="base_footprint">
    <inertial>
      <mass value="0.0001"/>
      <origin xyz="0 0 0"/>
      <inertia ixx="0.0001" ixy="0.0" ixz="0.0" iyy="0.0001" iyz="0.0" izz="0.0001"/>
    </inertial>
    <visual>
      <origin rpy="0 0 0" xyz="0 0 0"/>
      <geometry>
        <box size="0.001 0.001 0.001"/>
      </geometry>
    </visual>
  </link>
  <joint name="base_footprint_joint" type="fixed">
    <origin rpy="0 0 0" xyz="0 0 0.39"/>
    <parent link="base_footprint"/>
    <child link="base_link"/>
  </joint>
  <link name="base_link">
    <collision>
      <origin rpy="0 0 0" xyz="0 0 0"/>
      <geometry>
        <box size="0.91 0.6 0.58"/>
      </geometry>
    </collision>
    <visual>
      <geometry>
        <box size="0.91 0.6 0.58"/>
      </geometry>
      <material name="blue"/>
    </visual>
    <inertial>
      <mass value="20"/>
      <origin rpy="0.0 0.0 0.0" xyz="0.0 0.0 0.0"/>
      <inertia ixx="1.16066666667" ixy="0.0" ixz="0.0" iyy="1.94083333333" iyz="0.0" izz="1.98016666667"/>
    </inertial>
  </link>
  <link name="camera_pole">
    <collision>
      <origin rpy="0 0 0" xyz=".43 0 .62"/>
      <geometry>
        <box size=".05 .1 .66"/>
      </geometry>
    </collision>
    <visual>
      <origin rpy="0 0 0 " xyz=".43 0 .62"/>
      <geometry>
        <box size=".05 .1 .66"/>
      </geometry>
      <material name="black"/>
      <origin rpy="0 0 0" xyz="0 0 0"/>
    </visual>
  </link>
  <joint name="camera_pole_joint" type="fixed">
    <parent link="base_link"/>
    <child link="camera_pole"/>
    <origin xyz="0 0 0"/>
  </joint>
  <joint name="camera_joint" type="fixed">
    <parent link="camera_pole"/>
    <child link="testKinect"/>
    <origin xyz="0 0 0"/>
  </joint>
  <link name="testKinect">
    <collision>
      <origin rpy="0 0 0" xyz="0 0 0"/>
      <geometry>
        <box size=".05 .3 .1"/>
      </geometry>
    </collision>
    <visual>
      <origin rpy="0 0 0 " xyz=".43 0 .62"/>
      <geometry>
        <box size=".05 .1 .66"/>
      </geometry>
      <material name="black"/>
      <origin rpy="0 0 0" xyz="0 0 0"/>
    </visual>
  </link>
  <!-- joint name="${fb}_${lr}_roller_joint" type="continuous">
  <parent link="${fb}_${lr}_wheel"/>
  <child link="${fb}_${lr}_roller"/>
  <origin xyz="0.0 0.0 0.0" rpy="0.0 0.0 0.0"/>
  <axis xyz="${-(sideX * sideY)} 1.0 0.0"/>

</joint -->
  <joint name="hokuyo_joint" type="fixed">
    <axis xyz="0 1 0"/>
    <origin rpy="0 0 0" xyz=".6 0 0"/>
    <parent link="base_link"/>
    <child link="hokuyo_link"/>
  </joint>
  <!-- Hokuyo Laser -->
  <link name="hokuyo_link">
    <collision>
      <origin rpy="0 0 0" xyz="0 0 0"/>
      <geometry>
        <box size="0.1 0.1 0.1"/>
      </geometry>
    </collision>
    <visual>
      <origin rpy="0 0 0" xyz="0 0 0"/>
      <geometry>
        <mesh filename="file:///home/blanknc/igvc_ws/src/robot_description/meshes/hokuyo.dae"/>
      </geometry>
    </visual>
    <inertial>
      <mass value="1e-5"/>
      <origin rpy="0 0 0" xyz="0 0 0"/>
      <inertia ixx="1e-6" ixy="0" ixz="0" iyy="1e-6" iyz="0" izz="1e-6"/>
    </inertial>
  </link>
  <!-- Camera -->
  <!-- gazebo>
  <plugin name="${link_name}_controller" filename="libgazebo_ros_openni_kinect.so">
    <baseline>0.2</baseline>
    <alwaysOn>true</alwaysOn>
    <updateRate>1.0</updateRate>
    <cameraName>${camera_name}_ir</cameraName>
    <imageTopicName>/${camera_name}/depth/image_raw</imageTopicName>
    <cameraInfoTopicName>/${camera_name}/depth/camera_info</cameraInfoTopicName>
    <depthImageTopicName>/${camera_name}/depth/image_raw</depthImageTopicName>
    <depthImageInfoTopicName>/${camera_name}/depth/camera_info</depthImageInfoTopicName>
    <pointCloudTopicName>/${camera_name}/depth/points</pointCloudTopicName>
    <frameName>${frame_name}</frameName>
    <pointCloudCutoff>0.5</pointCloudCutoff>
    <distortionK1>0.00000001</distortionK1>
    <distortionK2>0.00000001</distortionK2>
    <distortionK3>0.00000001</distortionK3>
    <distortionT1>0.00000001</distortionT1>
    <distortionT2>0.00000001</distortionT2>
    <CxPrime>0</CxPrime>
    <Cx>0</Cx>
    <Cy>0</Cy>
    <focalLength>0</focalLength>
    <hackBaseline>0</hackBaseline>
  </plugin>
</gazebo -->
  <!-- hokuyo -->
  <gazebo reference="hokuyo_link">
    <sensor name="head_hokuyo_sensor" type="gpu_ray">
      <pose>0 0 0 0 0 0</pose>
      <visualize>true</visualize>
      <update_rate>40</update_rate>
      <ray>
        <scan>
          <horizontal>
            <samples>720</samples>
            <resolution>1</resolution>
            <min_angle>-1.570796</min_angle>
            <max_angle>1.570796</max_angle>
          </horizontal>
        </scan>
        <range>
          <min>0.10</min>
          <max>30.0</max>
          <resolution>0.01</resolution>
        </range>
        <noise>
          <type>gaussian</type>
          <!-- Noise parameters based on published spec for Hokuyo laser
               achieving "+-30mm" accuracy at range < 10m.  A mean of 0.0m and
               stddev of 0.01m will put 99.7% of samples within 0.03m of the true
               reading. -->
          <mean>0.0</mean>
          <stddev>0.01</stddev>
        </noise>
      </ray>
      <plugin filename="libgazebo_ros_gpu_laser.so" name="gazebo_ros_head_hokuyo_controller">
        <topicName>/laser_scan</topicName>
        <frameName>hokuyo_link</frameName>
      </plugin>
    </sensor>
  </gazebo>
  <joint name="front_left_wheel_joint" type="continuous">
    <axis xyz="0 1 0"/>
    <parent link="base_link"/>
    <child link="front_left_wheel"/>
    <origin rpy="0 0 0" xyz="0.33 0.325 -0.24"/>
    <!-- "0.133333333333 0 -0.085   -.19"-->
    <limit effort="100.0" velocity="100.0"/>
    <dynamics damping="0.0" friction="0.0"/>
  </joint>
  <link name="front_left_wheel">
    <collision>
      <origin rpy="1.57075 0 0" xyz="0 0 0"/>
      <geometry>
        <cylinder length="0.05" radius="0.1"/>
      </geometry>
    </collision>
    <visual>
      <origin rpy="1.57075 0 0" xyz="0 0 0"/>
      <geometry>
        <cylinder length="0.05" radius="0.1"/>
      </geometry>
      <material name="white"/>
      <origin rpy="0 0 0" xyz="0 0 0"/>
    </visual>
    <inertial>
      <mass value="1"/>
      <origin rpy="1.570796325 0.0 0.0" xyz="0.0 0.0 0.0"/>
      <inertia ixx="0.00270833225" ixy="0.0" ixz="0.0" iyy="0.00270833225" iyz="0.0" izz="0.005"/>
    </inertial>
  </link>
  <gazebo reference="front_left_wheel_joint">
    <dynamics damping="0.0" friction="0.0"/>
  </gazebo>
  <gazebo reference="front_left_wheel">
    <selfCollide>false</selfCollide>
    <static>false</static>
    <turnGravityOff>false</turnGravityOff>
    <material>Gazebo/Grey</material>
  </gazebo>
  <joint name="front_left_roller_joint" type="continuous">
    <parent link="front_left_wheel"/>
    <child link="front_left_roller"/>
    <origin rpy="0.0 0.0 0.0" xyz="0.0 0.0 0.0"/>
    <axis xyz="-0.10725 1.0 0.0"/>
    <limit effort="100.0" velocity="100.0"/>
    <dynamics damping="0.0" friction="0.0"/>
  </joint>
  <gazebo reference="front_left_roller_joint">
    <dynamics damping="0.0" friction="0.0"/>
  </gazebo>
  <link name="front_left_roller">
    <collision>
      <geometry>
        <sphere radius="0.0758"/>
      </geometry>
      <origin rpy="0.0 0.0 0.0" xyz="0.0 0.0 0.0"/>
    </collision>
    <inertial>
      <mass value="0.9072"/>
      <origin rpy="1.570796325 0.0 0.0" xyz="0.0 0.0 0.0"/>
      <inertia ixx="0.00147011096396" ixy="0.0" ixz="0.0" iyy="0.00147011096396" iyz="0.0" izz="0.002606222304"/>
    </inertial>
  </link>
  <gazebo reference="front_left_roller">
    <selfCollide>false</selfCollide>
    <static>false</static>
    <turnGravityOff>false</turnGravityOff>
    <kp>1000000.0</kp>
    <kd>100.0</kd>
    <mu1>1.0</mu1>
    <mu2>1.0</mu2>
    <fdir1>0 1 0</fdir1>
    <maxVel>10.0</maxVel>
    <minDepth>0.00</minDepth>
  </gazebo>
  <transmission name="front_left_wheel_transmission">
    <type>transmission_interface/SimpleTransmission</type>
    <actuator name="wheel_motor_fl"/>
    <joint name="front_left_wheel_joint"/>
    <mechanicalReduction>10</mechanicalReduction>
  </transmission>
  <joint name="back_left_wheel_joint" type="continuous">
    <axis xyz="0 1 0"/>
    <parent link="base_link"/>
    <child link="back_left_wheel"/>
    <origin rpy="0 0 0" xyz="-0.33 0.325 -0.24"/>
    <!-- "0.133333333333 0 -0.085   -.19"-->
    <limit effort="100.0" velocity="100.0"/>
    <dynamics damping="0.0" friction="0.0"/>
  </joint>
  <link name="back_left_wheel">
    <collision>
      <origin rpy="1.57075 0 0" xyz="0 0 0"/>
      <geometry>
        <cylinder length="0.05" radius="0.1"/>
      </geometry>
    </collision>
    <visual>
      <origin rpy="1.57075 0 0" xyz="0 0 0"/>
      <geometry>
        <cylinder length="0.05" radius="0.1"/>
      </geometry>
      <material name="white"/>
      <origin rpy="0 0 0" xyz="0 0 0"/>
    </visual>
    <inertial>
      <mass value="1"/>
      <origin rpy="1.570796325 0.0 0.0" xyz="0.0 0.0 0.0"/>
      <inertia ixx="0.00270833225" ixy="0.0" ixz="0.0" iyy="0.00270833225" iyz="0.0" izz="0.005"/>
    </inertial>
  </link>
  <gazebo reference="back_left_wheel_joint">
    <dynamics damping="0.0" friction="0.0"/>
  </gazebo>
  <gazebo reference="back_left_wheel">
    <selfCollide>false</selfCollide>
    <static>false</static>
    <turnGravityOff>false</turnGravityOff>
    <material>Gazebo/Grey</material>
  </gazebo>
  <joint name="back_left_roller_joint" type="continuous">
    <parent link="back_left_wheel"/>
    <child link="back_left_roller"/>
    <origin rpy="0.0 0.0 0.0" xyz="0.0 0.0 0.0"/>
    <axis xyz="0.10725 1.0 0.0"/>
    <limit effort="100.0" velocity="100.0"/>
    <dynamics damping="0.0" friction="0.0"/>
  </joint>
  <gazebo reference="back_left_roller_joint">
    <dynamics damping="0.0" friction="0.0"/>
  </gazebo>
  <link name="back_left_roller">
    <collision>
      <geometry>
        <sphere radius="0.0758"/>
      </geometry>
      <origin rpy="0.0 0.0 0.0" xyz="0.0 0.0 0.0"/>
    </collision>
    <inertial>
      <mass value="0.9072"/>
      <origin rpy="1.570796325 0.0 0.0" xyz="0.0 0.0 0.0"/>
      <inertia ixx="0.00147011096396" ixy="0.0" ixz="0.0" iyy="0.00147011096396" iyz="0.0" izz="0.002606222304"/>
    </inertial>
  </link>
  <gazebo reference="back_left_roller">
    <selfCollide>false</selfCollide>
    <static>false</static>
    <turnGravityOff>false</turnGravityOff>
    <kp>1000000.0</kp>
    <kd>100.0</kd>
    <mu1>1.0</mu1>
    <mu2>1.0</mu2>
    <fdir1>0 1 0</fdir1>
    <maxVel>10.0</maxVel>
    <minDepth>0.00</minDepth>
  </gazebo>
  <transmission name="back_left_wheel_transmission">
    <type>transmission_interface/SimpleTransmission</type>
    <actuator name="wheel_motor_fl"/>
    <joint name="back_left_wheel_joint"/>
    <mechanicalReduction>10</mechanicalReduction>
  </transmission>
  <joint name="back_right_wheel_joint" type="continuous">
    <axis xyz="0 1 0"/>
    <parent link="base_link"/>
    <child link="back_right_wheel"/>
    <origin rpy="0 0 0" xyz="0.33 -0.325 -0.24"/>
    <!-- "0.133333333333 0 -0.085   -.19"-->
    <limit effort="100.0" velocity="100.0"/>
    <dynamics damping="0.0" friction="0.0"/>
  </joint>
  <link name="back_right_wheel">
    <collision>
      <origin rpy="1.57075 0 0" xyz="0 0 0"/>
      <geometry>
        <cylinder length="0.05" radius="0.1"/>
      </geometry>
    </collision>
    <visual>
      <origin rpy="1.57075 0 0" xyz="0 0 0"/>
      <geometry>
        <cylinder length="0.05" radius="0.1"/>
      </geometry>
      <material name="white"/>
      <origin rpy="0 0 0" xyz="0 0 0"/>
    </visual>
    <inertial>
      <mass value="1"/>
      <origin rpy="1.570796325 0.0 0.0" xyz="0.0 0.0 0.0"/>
      <inertia ixx="0.00270833225" ixy="0.0" ixz="0.0" iyy="0.00270833225" iyz="0.0" izz="0.005"/>
    </inertial>
  </link>
  <gazebo reference="back_right_wheel_joint">
    <dynamics damping="0.0" friction="0.0"/>
  </gazebo>
  <gazebo reference="back_right_wheel">
    <selfCollide>false</selfCollide>
    <static>false</static>
    <turnGravityOff>false</turnGravityOff>
    <material>Gazebo/Grey</material>
  </gazebo>
  <joint name="back_right_roller_joint" type="continuous">
    <parent link="back_right_wheel"/>
    <child link="back_right_roller"/>
    <origin rpy="0.0 0.0 0.0" xyz="0.0 0.0 0.0"/>
    <axis xyz="0.10725 1.0 0.0"/>
    <limit effort="100.0" velocity="100.0"/>
    <dynamics damping="0.0" friction="0.0"/>
  </joint>
  <gazebo reference="back_right_roller_joint">
    <dynamics damping="0.0" friction="0.0"/>
  </gazebo>
  <link name="back_right_roller">
    <collision>
      <geometry>
        <sphere radius="0.0758"/>
      </geometry>
      <origin rpy="0.0 0.0 0.0" xyz="0.0 0.0 0.0"/>
    </collision>
    <inertial>
      <mass value="0.9072"/>
      <origin rpy="1.570796325 0.0 0.0" xyz="0.0 0.0 0.0"/>
      <inertia ixx="0.00147011096396" ixy="0.0" ixz="0.0" iyy="0.00147011096396" iyz="0.0" izz="0.002606222304"/>
    </inertial>
  </link>
  <gazebo reference="back_right_roller">
    <selfCollide>false</selfCollide>
    <static>false</static>
    <turnGravityOff>false</turnGravityOff>
    <kp>1000000.0</kp>
    <kd>100.0</kd>
    <mu1>1.0</mu1>
    <mu2>1.0</mu2>
    <fdir1>0 1 0</fdir1>
    <maxVel>10.0</maxVel>
    <minDepth>0.00</minDepth>
  </gazebo>
  <transmission name="back_right_wheel_transmission">
    <type>transmission_interface/SimpleTransmission</type>
    <actuator name="wheel_motor_fl"/>
    <joint name="back_right_wheel_joint"/>
    <mechanicalReduction>10</mechanicalReduction>
  </transmission>
  <joint name="front_right_wheel_joint" type="continuous">
    <axis xyz="0 1 0"/>
    <parent link="base_link"/>
    <child link="front_right_wheel"/>
    <origin rpy="0 0 0" xyz="-0.33 -0.325 -0.24"/>
    <!-- "0.133333333333 0 -0.085   -.19"-->
    <limit effort="100.0" velocity="100.0"/>
    <dynamics damping="0.0" friction="0.0"/>
  </joint>
  <link name="front_right_wheel">
    <collision>
      <origin rpy="1.57075 0 0" xyz="0 0 0"/>
      <geometry>
        <cylinder length="0.05" radius="0.1"/>
      </geometry>
    </collision>
    <visual>
      <origin rpy="1.57075 0 0" xyz="0 0 0"/>
      <geometry>
        <cylinder length="0.05" radius="0.1"/>
      </geometry>
      <material name="white"/>
      <origin rpy="0 0 0" xyz="0 0 0"/>
    </visual>
    <inertial>
      <mass value="1"/>
      <origin rpy="1.570796325 0.0 0.0" xyz="0.0 0.0 0.0"/>
      <inertia ixx="0.00270833225" ixy="0.0" ixz="0.0" iyy="0.00270833225" iyz="0.0" izz="0.005"/>
    </inertial>
  </link>
  <gazebo reference="front_right_wheel_joint">
    <dynamics damping="0.0" friction="0.0"/>
  </gazebo>
  <gazebo reference="front_right_wheel">
    <selfCollide>false</selfCollide>
    <static>false</static>
    <turnGravityOff>false</turnGravityOff>
    <material>Gazebo/Grey</material>
  </gazebo>
  <joint name="front_right_roller_joint" type="continuous">
    <parent link="front_right_wheel"/>
    <child link="front_right_roller"/>
    <origin rpy="0.0 0.0 0.0" xyz="0.0 0.0 0.0"/>
    <axis xyz="-0.10725 1.0 0.0"/>
    <limit effort="100.0" velocity="100.0"/>
    <dynamics damping="0.0" friction="0.0"/>
  </joint>
  <gazebo reference="front_right_roller_joint">
    <dynamics damping="0.0" friction="0.0"/>
  </gazebo>
  <link name="front_right_roller">
    <collision>
      <geometry>
        <sphere radius="0.0758"/>
      </geometry>
      <origin rpy="0.0 0.0 0.0" xyz="0.0 0.0 0.0"/>
    </collision>
    <inertial>
      <mass value="0.9072"/>
      <origin rpy="1.570796325 0.0 0.0" xyz="0.0 0.0 0.0"/>
      <inertia ixx="0.00147011096396" ixy="0.0" ixz="0.0" iyy="0.00147011096396" iyz="0.0" izz="0.002606222304"/>
    </inertial>
  </link>
  <gazebo reference="front_right_roller">
    <selfCollide>false</selfCollide>
    <static>false</static>
    <turnGravityOff>false</turnGravityOff>
    <kp>1000000.0</kp>
    <kd>100.0</kd>
    <mu1>1.0</mu1>
    <mu2>1.0</mu2>
    <fdir1>0 1 0</fdir1>
    <maxVel>10.0</maxVel>
    <minDepth>0.00</minDepth>
  </gazebo>
  <transmission name="front_right_wheel_transmission">
    <type>transmission_interface/SimpleTransmission</type>
    <actuator name="wheel_motor_fl"/>
    <joint name="front_right_wheel_joint"/>
    <mechanicalReduction>10</mechanicalReduction>
  </transmission>
  <gazebo>
    <plugin filename="libgazebo_ros_planar_move.so" name="object_controller">
      <commandTopic>cmd_vel</commandTopic>
      <odometryTopic>odom</odometryTopic>
      <odometryFrame>odom</odometryFrame>
      <odometryRate>20.0</odometryRate>
      <robotBaseFrame>base_link</robotBaseFrame>
    </plugin>
  </gazebo>
</robot>

